Workbook

Sheet Quote Calculator
A1: Client Fee Quote
A2: Fill in the yellow cells. Everything else calculates from the Rate Card tab. Example values shown – overwrite for each client.
A4: CLIENT PROFILE
A5: Client name | B5: Example Ltd
A6: Entity type | B6: Limited Company
A7: Turnover band | B7: £90k–£250k
A8: Complexity | B8: Standard
A9: Record quality | B9: Average
A10: Bookkeeping transactions per month | B10: 120
A11: Bank/card accounts | B11: 2
A12: Invoices processed per month | B12: 30
A13: Multi-currency? (Y/N) | B13: N
A14: VAT scheme (None/Standard/Flat Rate) | B14: Standard
A15: Partial exemption? (Y/N) | B15: N
A16: Employees on payroll | B16: 3
A17: Pay frequency (Monthly/Weekly) | B17: Monthly
A18: Auto-enrolment pension? (Y/N) | B18: Y
A19: P11Ds per year | B19: 1
A20: CIS contractor? (Y/N) | B20: N
A21: Subcontractors per month | B21: 0
A22: Directors/individuals needing SA returns | B22: 2
A23: Rental properties (total across returns) | B23: 1
A24: CGT disposals | B24: 0
A25: Returns with foreign income | B25: 0
A26: MTD ITSA quarterly updates per year | B26: 0
A27: Dividends declared per year | B27: 4
A28: Management accounts packs per year | B28: 4
A29: Registered office service? (Y/N) | B29: Y
A30: Pay annually upfront? (Y/N) | B30: N
A32: Multiplier (complexity × records) | B32: =INDEX('Rate Card'!$B$52:$B$54,MATCH($B$8,'Rate Card'!$A$52:$A$54,0))*INDEX('Rate Card'!$E$52:$E$54,MATCH($B$9,'Rate Card'!$D$52:$D$54,0)) -> 1.15
A33: Is a company? (CT600, sec, dividends) | B33: =IF(OR($B$6="Limited Company",$B$6="LLP"),"Y","N") -> Y
A35: Service | B35: Include? (Y/N) | C35: Annual fee (£) | D35: Monthly equivalent (£) | E35: Basis
A36: Bookkeeping | B36: Y | C36: =IF(B36="Y",('Rate Card'!$B$5+MAX(0,$B$10-'Rate Card'!$B$6)*'Rate Card'!$B$7+MAX(0,$B$11-1)*'Rate Card'!$B$8+$B$12*'Rate Card'!$B$10+IF($B$13="Y",'Rate Card'!$B$9,0))*12*$B$32,0) -> 1945.8 | D36: =C36/12 -> 162.15 | E36: Base + extra transactions, accounts & invoices × multiplier
A37: VAT returns | B37: =IF($B$14="None","N","Y") -> Y | C37: =IF(B37="Y",4*IF($B$14="Flat Rate",'Rate Card'!$B$13,'Rate Card'!$B$12)+IF($B$15="Y",'Rate Card'!$B$14,0),0) -> 300 | D37: =C37/12 -> 25 | E37: 4 quarterly returns
A38: Payroll | B38: =IF($B$16>0,"Y","N") -> Y | C38: =IF(B38="Y",IF($B$17="Weekly",52,12)*MAX('Rate Card'!$B$18,$B$16*'Rate Card'!$B$17)+IF($B$18="Y",12*'Rate Card'!$B$19,0)+$B$19*'Rate Card'!$B$20,0) -> 435 | D38: =C38/12 -> 36.25 | E38: Per run (min charge) + pension + P11Ds
A39: CIS returns | B39: =$B$20 -> N | C39: =IF(B39="Y",12*('Rate Card'!$B$21+$B$21*'Rate Card'!$B$22),0) -> 0 | D39: =C39/12 -> 0 | E39: Monthly CIS300
A40: Year-end accounts | B40: Y | C40: =IF(B40="Y",INDEX('Rate Card'!$B$58:$F$62,MATCH($B$6,'Rate Card'!$A$58:$A$62,0),MATCH($B$7,'Rate Card'!$B$57:$F$57,0))*$B$32,0) -> 977.5 | D40: =C40/12 -> 81.458333 | E40: Entity × turnover table × multiplier
A41: Corporation tax return (CT600) | B41: =IF($B$6="Limited Company","Y","N") -> Y | C41: =IF(B41="Y",'Rate Card'!$B$24,0) -> 250 | D41: =C41/12 -> 20.833333 | E41: Annual
A42: Partnership return (SA800) | B42: =IF(OR($B$6="Partnership",$B$6="LLP"),"Y","N") -> N | C42: =IF(B42="Y",'Rate Card'!$B$29,0) -> 0 | D42: =C42/12 -> 0 | E42: Annual
A43: Self assessment returns | B43: =IF($B$22>0,"Y","N") -> Y | C43: =IF(B43="Y",$B$22*'Rate Card'!$B$25+$B$23*'Rate Card'!$B$26+$B$24*'Rate Card'!$B$27+$B$25*'Rate Card'!$B$28,0) -> 475 | D43: =C43/12 -> 39.583333 | E43: Per return + add-ons
...

Sheet Rate Card
A1: UniFinancial Solutions – Rate Card (edit blue figures to set your prices)
A2: All prices exclude VAT. Blue = your input. Figures are starting suggestions based on typical UK small-practice fees – review against your own market.
A4: Bookkeeping
A5: Base fee (includes transactions below) | B5: 60 | C5: per month
A6: Transactions included in base | B6: 50 | C6: per month
A7: Each additional transaction | B7: 0.8 | C7: per transaction
A8: Each bank/card account beyond the first | B8: 10 | C8: per month
A9: Multi-currency handling | B9: 20 | C9: per month
A10: Sales/purchase invoice processing | B10: 0.5 | C10: per invoice
A11: VAT
A12: VAT return – standard/cash accounting | B12: 75 | C12: per return
A13: VAT return – flat rate scheme | B13: 50 | C13: per return
A14: Partial exemption calculations | B14: 150 | C14: per year
A15: VAT registration (one-off) | B15: 100 | C15: one-off
A16: Payroll
A17: Per employee per pay run | B17: 5 | C17: per employee/run
A18: Minimum charge per pay run | B18: 20 | C18: per run
A19: Pension auto-enrolment administration | B19: 10 | C19: per month
A20: P11D per employee (incl. P11D(b)) | B20: 75 | C20: per P11D
A21: CIS monthly return | B21: 25 | C21: per month
A22: Per subcontractor verified/paid | B22: 2 | C22: per sub/month
A23: Tax returns
A24: Corporation tax return (CT600) | B24: 250 | C24: per year
A25: Self assessment return – simple | B25: 200 | C25: per return
A26: Add per rental property | B26: 75 | C26: per property
A27: Add per capital gains disposal | B27: 150 | C27: per disposal
A28: Add foreign income | B28: 100 | C28: per return
A29: Partnership tax return (SA800) | B29: 250 | C29: per year
A30: MTD for Income Tax quarterly update | B30: 40 | C30: per update
A31: Company secretarial
A32: Confirmation statement (our fee) | B32: 60 | C32: per year
A33: Companies House filing fee (disbursement – check current fee) | B33: 50 | C33: per year
A34: Registered office address | B34: 120 | C34: per year
A35: Dividend vouchers & board minutes | B35: 25 | C35: per dividend
A36: Management information
A37: Management accounts pack | B37: 150 | C37: per pack
A38: Cash flow forecast / budget | B38: 350 | C38: per forecast
A39: One-off / project work
A40: Company formation | B40: 150 | C40: one-off
A41: Alphabet share restructure (articles, resolutions, filings, tax note) | B41: 450 | C41: one-off
...

Sheet Co Sec Menu
A1: Company secretarial menu – FCLS supplier costs (Price List Feb 2026) with your resale price
A2: Your markup on FCLS cost | B2: 0.5 | C2: Round resale price up to nearest £ | E2: 5
A3: Enter quantities in column H for a client quote; the total feeds the Quote Calculator one-off section → | F3: Quote total (ex VAT) | G3: =SUM(G6:G106) -> 0
A5: Category | B5: Service | C5: FCLS price | D5: FCLS VAT basis | E5: FCLS cost ex VAT | F5: Your resale price (ex VAT) | G5: Line total | H5: Qty | I5: Your current Rate Card price | J5: Note
A6: Company formation
A7: Company formation | B7: Private Limited | C7: 153 | D7: inc VAT | E7: =IF(ISNUMBER(C7),IF(D7="inc VAT",C7/1.2,C7),0) -> 127.5 | F7: =IF(E7=0,"POA",CEILING(E7*(1+$B$2),$E$2)) -> 195 | G7: =IF(ISNUMBER(F7),F7*H7,0) -> 0 | H7: 0 | I7: ='Rate Card'!$B$40 -> 150 | J7: Includes Companies House fee (no VAT on that part) – ex-VAT cost is approximate
A8: Company formation | B8: Flat Management | C8: 223 | D8: inc VAT | E8: =IF(ISNUMBER(C8),IF(D8="inc VAT",C8/1.2,C8),0) -> 185.83333 | F8: =IF(E8=0,"POA",CEILING(E8*(1+$B$2),$E$2)) -> 280 | G8: =IF(ISNUMBER(F8),F8*H8,0) -> 0 | H8: 0
A9: Company formation | B9: Charity | C9: 258 | D9: inc VAT | E9: =IF(ISNUMBER(C9),IF(D9="inc VAT",C9/1.2,C9),0) -> 215 | F9: =IF(E9=0,"POA",CEILING(E9*(1+$B$2),$E$2)) -> 325 | G9: =IF(ISNUMBER(F9),F9*H9,0) -> 0 | H9: 0
A10: Company formation | B10: Guarantee | C10: 223 | D10: inc VAT | E10: =IF(ISNUMBER(C10),IF(D10="inc VAT",C10/1.2,C10),0) -> 185.83333 | F10: =IF(E10=0,"POA",CEILING(E10*(1+$B$2),$E$2)) -> 280 | G10: =IF(ISNUMBER(F10),F10*H10,0) -> 0 | H10: 0
A11: Company formation | B11: PLC | C11: 218 | D11: inc VAT | E11: =IF(ISNUMBER(C11),IF(D11="inc VAT",C11/1.2,C11),0) -> 181.66667 | F11: =IF(E11=0,"POA",CEILING(E11*(1+$B$2),$E$2)) -> 275 | G11: =IF(ISNUMBER(F11),F11*H11,0) -> 0 | H11: 0
A12: Company formation | B12: CIC | C12: 273 | D12: inc VAT | E12: =IF(ISNUMBER(C12),IF(D12="inc VAT",C12/1.2,C12),0) -> 227.5 | F12: =IF(E12=0,"POA",CEILING(E12*(1+$B$2),$E$2)) -> 345 | G12: =IF(ISNUMBER(F12),F12*H12,0) -> 0 | H12: 0
A13: Company formation | B13: LLP | C13: 213 | D13: inc VAT | E13: =IF(ISNUMBER(C13),IF(D13="inc VAT",C13/1.2,C13),0) -> 177.5 | F13: =IF(E13=0,"POA",CEILING(E13*(1+$B$2),$E$2)) -> 270 | G13: =IF(ISNUMBER(F13),F13*H13,0) -> 0 | H13: 0
A14: Company formation | B14: Right to Manage | C14: 223 | D14: inc VAT | E14: =IF(ISNUMBER(C14),IF(D14="inc VAT",C14/1.2,C14),0) -> 185.83333 | F14: =IF(E14=0,"POA",CEILING(E14*(1+$B$2),$E$2)) -> 280 | G14: =IF(ISNUMBER(F14),F14*H14,0) -> 0 | H14: 0
A15: Company formation | B15: CIO | C15: 458 | D15: inc VAT | E15: =IF(ISNUMBER(C15),IF(D15="inc VAT",C15/1.2,C15),0) -> 381.66667 | F15: =IF(E15=0,"POA",CEILING(E15*(1+$B$2),$E$2)) -> 575 | G15: =IF(ISNUMBER(F15),F15*H15,0) -> 0 | H15: 0
A16: Company formation | B16: Unlimited | C16: 358 | D16: inc VAT | E16: =IF(ISNUMBER(C16),IF(D16="inc VAT",C16/1.2,C16),0) -> 298.33333 | F16: =IF(E16=0,"POA",CEILING(E16*(1+$B$2),$E$2)) -> 450 | G16: =IF(ISNUMBER(F16),F16*H16,0) -> 0 | H16: 0
A17: Company formation | B17: LP | C17: 178 | D17: inc VAT | E17: =IF(ISNUMBER(C17),IF(D17="inc VAT",C17/1.2,C17),0) -> 148.33333 | F17: =IF(E17=0,"POA",CEILING(E17*(1+$B$2),$E$2)) -> 225 | G17: =IF(ISNUMBER(F17),F17*H17,0) -> 0 | H17: 0
A18: Company formation | B18: B-Corp | C18: 183 | D18: inc VAT | E18: =IF(ISNUMBER(C18),IF(D18="inc VAT",C18/1.2,C18),0) -> 152.5 | F18: =IF(E18=0,"POA",CEILING(E18*(1+$B$2),$E$2)) -> 230 | G18: =IF(ISNUMBER(F18),F18*H18,0) -> 0 | H18: 0
A19: Company formation | B19: Ready Made company | C19: 203 | D19: inc VAT | E19: =IF(ISNUMBER(C19),IF(D19="inc VAT",C19/1.2,C19),0) -> 169.16667 | F19: =IF(E19=0,"POA",CEILING(E19*(1+$B$2),$E$2)) -> 255 | G19: =IF(ISNUMBER(F19),F19*H19,0) -> 0 | H19: 0
... A25: Company formation | B25: Add-on: register for unlimited | C25: 75 | D25: inc VAT | E25: =IF(ISNUMBER(C25),IF(D25="inc VAT",C25/1.2,C25),0) -> 62.5 | F25: =IF(E25=0,"POA",CEILING(E25*(1+$B$2),$E$2)) -> 95 | G25: =IF(ISNUMBER(F25),F25*H25,0) -> 0 | H25: 0
A26: Share & capital work
A27: Share & capital work | B27: Share restructure – standard class shares (e.g. alphabet shares) | C27: 200 | D27: ex VAT | E27: =IF(ISNUMBER(C27),IF(D27="inc VAT",C27/1.2,C27),0) -> 200 | F27: =IF(E27=0,"POA",CEILING(E27*(1+$B$2),$E$2)) -> 300 | G27: =IF(ISNUMBER(F27),F27*H27,0) -> 0 | H27: 0 | I27: ='Rate Card'!$B$41 -> 450 | J27: FCLS does the legal paperwork only – your £450 also covers the tax note
A28: Share & capital work | B28: Share restructure with allotments and/or transfers | C28: 220 | D28: ex VAT | E28: =IF(ISNUMBER(C28),IF(D28="inc VAT",C28/1.2,C28),0) -> 220 | F28: =IF(E28=0,"POA",CEILING(E28*(1+$B$2),$E$2)) -> 330 | G28: =IF(ISNUMBER(F28),F28*H28,0) -> 0 | H28: 0
A29: Share & capital work | B29: Share restructure incl. bonus issue or sub-division | C29: 250 | D29: ex VAT | E29: =IF(ISNUMBER(C29),IF(D29="inc VAT",C29/1.2,C29),0) -> 250 | F29: =IF(E29=0,"POA",CEILING(E29*(1+$B$2),$E$2)) -> 375 | G29: =IF(ISNUMBER(F29),F29*H29,0) -> 0 | H29: 0
A30: Share & capital work | B30: Share restructure incl. redeemable preference shares | C30: 250 | D30: ex VAT | E30: =IF(ISNUMBER(C30),IF(D30="inc VAT",C30/1.2,C30),0) -> 250 | F30: =IF(E30=0,"POA",CEILING(E30*(1+$B$2),$E$2)) -> 375 | G30: =IF(ISNUMBER(F30),F30*H30,0) -> 0 | H30: 0
A31: Share & capital work | B31: Purchase of own shares | C31: 230 | D31: ex VAT | E31: =IF(ISNUMBER(C31),IF(D31="inc VAT",C31/1.2,C31),0) -> 230 | F31: =IF(E31=0,"POA",CEILING(E31*(1+$B$2),$E$2)) -> 345 | G31: =IF(ISNUMBER(F31),F31*H31,0) -> 0 | H31: 0
A32: Share & capital work | B32: Purchase of own shares – out of cash with articles | C32: 400 | D32: ex VAT | E32: =IF(ISNUMBER(C32),IF(D32="inc VAT",C32/1.2,C32),0) -> 400 | F32: =IF(E32=0,"POA",CEILING(E32*(1+$B$2),$E$2)) -> 600 | G32: =IF(ISNUMBER(F32),F32*H32,0) -> 0 | H32: 0
A33: Share & capital work | B33: Purchase of own shares – out of capital | C33: 500 | D33: ex VAT | E33: =IF(ISNUMBER(C33),IF(D33="inc VAT",C33/1.2,C33),0) -> 500 | F33: =IF(E33=0,"POA",CEILING(E33*(1+$B$2),$E$2)) -> 750 | G33: =IF(ISNUMBER(F33),F33*H33,0) -> 0 | H33: 0
A34: Share & capital work | B34: Reduction of capital | C34: 230 | D34: ex VAT | E34: =IF(ISNUMBER(C34),IF(D34="inc VAT",C34/1.2,C34),0) -> 230 | F34: =IF(E34=0,"POA",CEILING(E34*(1+$B$2),$E$2)) -> 345 | G34: =IF(ISNUMBER(F34),F34*H34,0) -> 0 | H34: 0
A35: Share & capital work | B35: Share for share exchange | C35: 220 | D35: ex VAT | E35: =IF(ISNUMBER(C35),IF(D35="inc VAT",C35/1.2,C35),0) -> 220 | F35: =IF(E35=0,"POA",CEILING(E35*(1+$B$2),$E$2)) -> 330 | G35: =IF(ISNUMBER(F35),F35*H35,0) -> 0 | H35: 0
A36: Share & capital work | B36: Sub-division or consolidation | C36: 200 | D36: ex VAT | E36: =IF(ISNUMBER(C36),IF(D36="inc VAT",C36/1.2,C36),0) -> 200 | F36: =IF(E36=0,"POA",CEILING(E36*(1+$B$2),$E$2)) -> 300 | G36: =IF(ISNUMBER(F36),F36*H36,0) -> 0 | H36: 0
A37: Share & capital work | B37: Redemption | C37: 130 | D37: ex VAT | E37: =IF(ISNUMBER(C37),IF(D37="inc VAT",C37/1.2,C37),0) -> 130 | F37: =IF(E37=0,"POA",CEILING(E37*(1+$B$2),$E$2)) -> 195 | G37: =IF(ISNUMBER(F37),F37*H37,0) -> 0 | H37: 0
A38: Share & capital work | B38: Bonus or rights issue | C38: 160 | D38: ex VAT | E38: =IF(ISNUMBER(C38),IF(D38="inc VAT",C38/1.2,C38),0) -> 160 | F38: =IF(E38=0,"POA",CEILING(E38*(1+$B$2),$E$2)) -> 240 | G38: =IF(ISNUMBER(F38),F38*H38,0) -> 0 | H38: 0
A39: Share & capital work | B39: Allotment | C39: 120 | D39: ex VAT | E39: =IF(ISNUMBER(C39),IF(D39="inc VAT",C39/1.2,C39),0) -> 120 | F39: =IF(E39=0,"POA",CEILING(E39*(1+$B$2),$E$2)) -> 180 | G39: =IF(ISNUMBER(F39),F39*H39,0) -> 0 | H39: 0 | I39: ='Rate Card'!$B$42 -> 150
A40: Share & capital work | B40: Transfer | C40: 70 | D40: ex VAT | E40: =IF(ISNUMBER(C40),IF(D40="inc VAT",C40/1.2,C40),0) -> 70 | F40: =IF(E40=0,"POA",CEILING(E40*(1+$B$2),$E$2)) -> 105 | G40: =IF(ISNUMBER(F40),F40*H40,0) -> 0 | H40: 0 | I40: ='Rate Card'!$B$42 -> 150
A41: Other company services
A42: Other company services | B42: Update of articles | C42: 200 | D42: ex VAT | E42: =IF(ISNUMBER(C42),IF(D42="inc VAT",C42/1.2,C42),0) -> 200 | F42: =IF(E42=0,"POA",CEILING(E42*(1+$B$2),$E$2)) -> 300 | G42: =IF(ISNUMBER(F42),F42*H42,0) -> 0 | H42: 0
A43: Other company services | B43: Electronic change of name | C43: 62 | D43: ex VAT | E43: =IF(ISNUMBER(C43),IF(D43="inc VAT",C43/1.2,C43),0) -> 62 | F43: =IF(E43=0,"POA",CEILING(E43*(1+$B$2),$E$2)) -> 95 | G43: =IF(ISNUMBER(F43),F43*H43,0) -> 0 | H43: 0
A44: Other company services | B44: Simultaneous change of name | C44: 220 | D44: ex VAT | E44: =IF(ISNUMBER(C44),IF(D44="inc VAT",C44/1.2,C44),0) -> 220 | F44: =IF(E44=0,"POA",CEILING(E44*(1+$B$2),$E$2)) -> 330 | G44: =IF(ISNUMBER(F44),F44*H44,0) -> 0 | H44: 0
A45: Other company services | B45: Re-registration / conversion | C45: 400 | D45: ex VAT | E45: =IF(ISNUMBER(C45),IF(D45="inc VAT",C45/1.2,C45),0) -> 400 | F45: =IF(E45=0,"POA",CEILING(E45*(1+$B$2),$E$2)) -> 600 | G45: =IF(ISNUMBER(F45),F45*H45,0) -> 0 | H45: 0
A46: Other company services | B46: Reconstruction of statutory registers | C46: POA | D46: ex VAT | E46: =IF(ISNUMBER(C46),IF(D46="inc VAT",C46/1.2,C46),0) -> 0 | F46: =IF(E46=0,"POA",CEILING(E46*(1+$B$2),$E$2)) -> POA | G46: =IF(ISNUMBER(F46),F46*H46,0) -> 0 | H46: 0
...

Sheet Competitor Research
A1: Hertfordshire competitor pricing research (gathered 23–24 Oct 2026 from public web pages)
A2: Figures are advertised 'from' prices or published ranges, ex VAT unless stated. Not verified with the firms – treat as indicative and re-check before relying on them.
A4: Firm / source | B4: Area | C4: Type | D4: Pricing model | E4: Sole trader | F4: Limited company | G4: Self assessment | H4: Bookkeeping | I4: VAT | J4: Payroll | K4: Other | L4: What to learn | M4: Source
A5: A-Wise Accountants | B5: Hertford, Hatfield, Hemel, Watford, WGC, Hitchin | C5: Online/low-cost chain (town landing pages) | D5: Headline monthly package with 'was/now' discount | E5: From £10/m (shown discounted to £5) | F5: From £40/m (shown discounted to £20) | G5: Not published | H5: Not published | I5: Not published | J5: Not published | K5: Same page cloned per town for local SEO | L5: Low anchor price wins clicks; the real fee comes from add-ons. Expect clients to quote '£20 a month' at you – show what's excluded. | M5: https://a-wise.co.uk/accountants-in-hertford/
A6: RSBC | B6: St Albans, Hitchin, WGC | C6: Online/low-cost chain | D6: Tiered monthly packages | E6: £35/m + VAT | F6: £40/m + VAT | G6: Included in packages (scope unclear) | H6: Package from £35/m | I6: Not published | J6: Not published | K6: 'From £10 pm' headline | L6: Two simple price points by entity type – easy for a client to understand and buy online. | M6: https://www.rsbc.uk/accountants-in-st-albans
A7: Mazuma (via St Albans page) | B7: St Albans | C7: National online bookkeeping | D7: Fixed monthly bookkeeping | E7: — | F7: — | G7: — | H7: From £38/m + VAT | I7: — | J7: — | K7: Page ~2 years old | L7: Bookkeeping as a standalone subscription, not bundled. | M7: https://www.yourstalbansaccountants.co.uk/bookkeeping
A8: St Albans fixed-fee SA provider | B8: St Albans | C8: Specialist / directory | D8: Fixed fee per return, tiered by client type | E8: — | F8: — | G8: £199 simple; £249 landlord; £299 company director (+VAT) | H8: — | I8: — | J8: — | K8: Another St Albans firm: £136 all-in | L8: Tiering SA by client type (simple / landlord / director) is a clean model – UFS uses add-ons instead. | M8: https://selfassessmenttaxreturn.accountants/self-assessment-tax-return-in-st-albans/
A9: DiGiFiLiNG | B9: St Albans | C9: Online | D9: Fixed fee | E9: — | F9: — | G9: From £199 | H9: — | I9: — | J9: — | L9: Confirms ~£199 as the local anchor for a simple return. | M9: https://digifiling.co.uk/areas-we-serve/small-business-tax-accountant-in-st-albans-uk/
A10: Stevenage SA specialist | B10: Stevenage | C10: Specialist | D10: Fixed fee, filed before 31 Jan | E10: — | F10: — | G10: From £199 + VAT | H10: — | I10: — | J10: — | L10: Same £199 anchor. | M10: https://selfassessmenttaxreturn.accountants/self-assessment-tax-return-in-stevenage/
A11: WGC bookkeeping firm | B11: Welwyn Garden City | C11: Local bookkeeper | D11: Hours-capped monthly package | E11: — | F11: — | G11: — | H11: £79/m + VAT for up to 4 hrs (software extra) | I11: — | J11: — | L11: Capping by hours protects margin on messy clients – an alternative to UFS's per-transaction model. | M11: https://bookkeepingservices.accountants/small-businesses/welwyn-garden-city/
A12: WGC/St Albans hourly bookkeeper | B12: WGC / St Albans | C12: Local bookkeeper | D12: Hourly then move to fixed | E12: — | F12: Fixed Ltd package from £149/m | G12: — | H12: £15/hr + VAT | I12: — | J12: — | L12: Start hourly to learn the client's volume, then fix the fee – good for onboarding unknown clients. | M12: https://bookkeepingservices.accountants/bookkeeping-services/st-albans/
A13: Hertfordshire listing/directory | B13: Hertfordshire | C13: Directory price list | D13: Itemised menu | E13: — | F13: — | G13: — | H13: — | I13: £89/qtr + VAT | J13: £29/m + VAT up to 3 staff; +£10/m each extra | K13: Confirmation statement £92 + VAT | L13: An itemised menu makes add-ons visible and easy to upsell. | M13: https://www.accountingfirms.co.uk/app/services/payroll-services-in-hertfordshire
A14: Herts Accountants (blog) | B14: Hertfordshire | C14: Chartered firm | D14: Fixed annual fee bundle | E14: SA £150–£500/yr | F14: Accounts £500–£1,500/yr | G14: £150–£500 | H14: — | I14: £75–£200/qtr | J14: £5–£15 per employee/m | K14: No public monthly price – quote only | L14: Traditional firms hide price and sell on one agreed fixed fee covering everything. | M14: https://hertsaccountants.co.uk/blog/how-much-should-you-pay-accountant
A15: Blossom Accountants | B15: Hertfordshire | C15: Online | D15: Estimate ranges | E15: ~£30/m | F15: Up to £150+/m | G15: — | H15: — | I15: — | J15: — | K15: Says Herts sits mid-market | M15: https://blossomaccountants.co.uk/hertfordshire/
A16: VerifiedAccountants guide | B16: Hertfordshire / Hemel / WGC | C16: Fee guide | D16: Market ranges | E16: — | F16: Accounts + CT £750–£2,000/yr | G16: £150–£400 (most £200–£350) | H16: £100–£500/m | I16: £100–£300/qtr | J16: £50–£100/m minimum + £5–£15 per employee | K16: Monthly packages £100–£300; £300–£600 with bookkeeping, VAT, payroll | L16: Most useful benchmark for full-service fees. | M16: https://verifiedaccountants.co.uk/guides/accountant-cost/hertfordshire
A17: Bizhub365 guide | B17: Watford | C17: Fee guide | D17: Market ranges | E17: — | F17: £1,500–£3,500/yr | G17: £150–£300 | H17: — | I17: — | J17: — | K17: Hourly £50–£200 (Watford firm) | L17: Watford, nearer London, prices higher. | M17: https://www.bizhub365.com/find/accountant/watford/cost/
A18: KE Accounting Solutions | B18: Stevenage / Hertfordshire | C18: Local bookkeeping & accounts firm | D18: Tiered monthly packages by business size | E18: — | F18: £400/m basic Ltd (no staff); £750/m multi-staff payroll; £1,500/m full AP/AR & credit control | G18: — | H18: Hourly from £35/hr; entry packages from £150/m | I18: Included in tiers | J18: Included in tiers | K18: Xero/QuickBooks setup | L18: Premium positioning – sells outsourced finance function, not compliance. Shows the ceiling of the local market. | M18: https://keaccountingsolutions.co.uk/hertfordshire
A19: QK Accounts | B19: Beds / Herts / Bucks | C19: Online/regional | D19: Bronze/Silver/Gold bundles | E19: — | F19: Bronze £75/m (accounts, VAT, payroll up to 5); Silver £140/m; Gold £250/m | G19: — | H19: Standalone from £25/m | I19: Standalone £150/qtr | J19: Up to 5 staff in Bronze | K19: Free QuickBooks licence; Silver/Gold add monthly management meeting | L19: Good-better-best tiers with a 'meeting' upsell. Bundling VAT+payroll makes standalone VAT (£150) look expensive. | M19: https://www.qkaccounts.com/
A20: Connected Accounting (Bark) | B20: Hertfordshire | C20: Online, Xero partner | D20: Two flat packages | E20: £49/m + VAT (also landlords) | F20: £99/m + VAT | G20: Included | H20: Not stated | I20: Not stated | J20: Not stated | L20: Simple two-price model, landlords priced same as sole traders. | M20: https://www.bark.com/en/gb/bookkeeping-services/hertfordshire/
A21: Hertford hourly bookkeeper | B21: Hertford | C21: Local bookkeeper | D21: Hourly, no contract | E21: — | F21: — | G21: — | H21: £15/hr + VAT (Xero/QB/Sage) | I21: — | J21: — | K21: No monthly contract | L21: Low hourly rate – sets client expectation for basic data entry. | M21: https://bookkeepingservices.accountants/bookkeeping-services/hertford/
A22: Bishop's Stortford directory | B22: Bishop's Stortford | C22: Directory average | D22: Entry monthly price | E22: From £60/m + VAT | F22: From £95/m + VAT | G22: £150–£400/yr | H22: — | I22: — | J22: — | K22: Basic Ltd accounts £700–£1,200/yr | L22: East Herts entry prices sit above the online chains. | M22: https://businessfinancing.co.uk/accounting/bishops-stortford-accountants/
A23: Landlord specialist | B23: Bishop's Stortford | C23: Niche specialist | D23: Monthly retainer | E23: Landlords £100–£300/m | F23: — | G23: Included | H23: — | I23: — | J23: — | L23: Niche specialists charge well above general firms – landlord niche worth considering. | M23: https://accountants-for-landlords.co.uk/near-me/hertfordshire-bishops-stortford/
A24: Mazuma | B24: National online | C24: Online | D24: Monthly plans by turnover | E24: — | F24: £98–£140/m + VAT (~£1,176/yr+) | G24: — | H24: Included | I24: — | J24: — | L24: National online benchmark for a full Ltd package. | M24: https://taxroot.co.uk/blog/best-online-accountant-uk-2026
A25: Crunch | B25: National online | C25: Online | D25: Monthly subscription + one-off SA | E25: From £27/m + VAT | F25: Not stated in source | G25: £200 + VAT (rises near Jan deadline) | H25: Software-led | I25: — | J25: — | K25: Deadline surge pricing | L25: Charging more for late SA work rewards early clients and covers January overtime. | M25: https://taxroot.co.uk/blog/best-online-accountant-uk-2026
A26: Aardvark Accounting | B26: National online | C26: Online | D26: Monthly package | E26: — | F26: £89/m + VAT | G26: — | H26: — | I26: — | J26: — | M26: https://taxroot.co.uk/blog/best-online-accountant-uk-2026
A27: TaxRoot | B27: National online | C27: Online | D27: Annual compliance-only | E27: — | F27: From £389/yr (accounts, CT, CT600) | G27: — | H27: — | I27: — | J27: — | L27: Compliance-only pricing – the absolute floor for Ltd year-end. | M27: https://taxroot.co.uk/blog/best-online-accountant-uk-2026
A28: Price Bailey | B28: Bishop's Stortford | C28: Large regional chartered firm | D28: Bespoke quote | E28: — | F28: Not published | G28: — | H28: — | I28: — | J28: — | L28: Large firms don't publish prices – they compete on expertise and advisory. | M28: https://www.pricebailey.co.uk/locations/bishops-stortford/

Sheet Market Comparison
A1: UFS prices vs Hertfordshire market (ex VAT)
A2: Blue = market figures from Competitor Research tab. Green = live link to your Rate Card, so this updates when you change your prices.
A4: Service | B4: Unit | C4: Market low | D4: Market typical | E4: Market high | F4: UFS price | G4: Position | H4: UFS vs typical | I4: Evidence
A5: Self assessment – simple | B5: per return | C5: 136 | D5: 199 | E5: 350 | F5: ='Rate Card'!$B$25 -> 200 | G5: =IF(F5<C5,"Below market",IF(F5>E5,"Above market",IF(F5<D5,"Low end of range","High end of range"))) -> High end of range | H5: =IF(D5=0,0,F5/D5-1) -> 0.0050251256 | I5: £136 all-in / £199 x3 local firms / guide £150–£400
A6: Self assessment – landlord (1 property) | B6: per return | C6: 200 | D6: 249 | E6: 400 | F6: ='Rate Card'!$B$25+'Rate Card'!$B$26 -> 275 | G6: =IF(F6<C6,"Below market",IF(F6>E6,"Above market",IF(F6<D6,"Low end of range","High end of range"))) -> High end of range | H6: =IF(D6=0,0,F6/D6-1) -> 0.10441767 | I6: £249 St Albans; guide range
A7: Ltd accounts + CT600 (turnover £90k–£250k) | B7: per year | C7: 750 | D7: 1100 | E7: 2000 | F7: ='Rate Card'!$C$60+'Rate Card'!$B$24 -> 1100 | G7: =IF(F7<C7,"Below market",IF(F7>E7,"Above market",IF(F7<D7,"Low end of range","High end of range"))) -> High end of range | H7: =IF(D7=0,0,F7/D7-1) -> 0 | I7: Herts/Hemel guide £750–£2,000; Herts Accountants £500–£1,500 accounts only
A8: Ltd accounts + CT600 (under £90k) | B8: per year | C8: 500 | D8: 850 | E8: 1500 | F8: ='Rate Card'!$B$60+'Rate Card'!$B$24 -> 900 | G8: =IF(F8<C8,"Below market",IF(F8>E8,"Above market",IF(F8<D8,"Low end of range","High end of range"))) -> High end of range | H8: =IF(D8=0,0,F8/D8-1) -> 0.058823529 | I8: Herts Accountants accounts £500+; guide £750+
A9: VAT return | B9: per quarter | C9: 75 | D9: 100 | E9: 300 | F9: ='Rate Card'!$B$12 -> 75 | G9: =IF(F9<C9,"Below market",IF(F9>E9,"Above market",IF(F9<D9,"Low end of range","High end of range"))) -> Low end of range | H9: =IF(D9=0,0,F9/D9-1) -> -0.25 | I9: £75–£200 Herts Accountants; £89 listing; guide £100–£300
A10: Payroll – per employee | B10: per employee/month | C10: 5 | D10: 10 | E10: 15 | F10: ='Rate Card'!$B$17 -> 5 | G10: =IF(F10<C10,"Below market",IF(F10>E10,"Above market",IF(F10<D10,"Low end of range","High end of range"))) -> Low end of range | H10: =IF(D10=0,0,F10/D10-1) -> -0.5 | I10: £5–£15 guide and Herts Accountants; £10 extra staff on listing
A11: Payroll – minimum monthly | B11: per month | C11: 29 | D11: 50 | E11: 100 | F11: ='Rate Card'!$B$18 -> 20 | G11: =IF(F11<C11,"Below market",IF(F11>E11,"Above market",IF(F11<D11,"Low end of range","High end of range"))) -> Below market | H11: =IF(D11=0,0,F11/D11-1) -> -0.6 | I11: £29 listing (up to 3 staff); guide £50–£100 minimum
A12: Confirmation statement (your fee) | B12: per year | C12: 50 | D12: 60 | E12: 92 | F12: ='Rate Card'!$B$32 -> 60 | G12: =IF(F12<C12,"Below market",IF(F12>E12,"Above market",IF(F12<D12,"Low end of range","High end of range"))) -> High end of range | H12: =IF(D12=0,0,F12/D12-1) -> 0 | I12: £50 + filing fee; £92 listing
A13: Bookkeeping – entry level | B13: per month | C13: 35 | D13: 79 | E13: 149 | F13: ='Rate Card'!$B$5 -> 60 | G13: =IF(F13<C13,"Below market",IF(F13>E13,"Above market",IF(F13<D13,"Low end of range","High end of range"))) -> Low end of range | H13: =IF(D13=0,0,F13/D13-1) -> -0.24050633 | I13: £35 RSBC; £38 Mazuma; £79 (4 hrs) WGC; £149 Ltd fixed
A14: Bookkeeping – fuller service | B14: per month | C14: 100 | D14: 250 | E14: 500 | F14: ='Rate Card'!$B$5+70*'Rate Card'!$B$7 -> 116 | G14: =IF(F14<C14,"Below market",IF(F14>E14,"Above market",IF(F14<D14,"Low end of range","High end of range"))) -> Low end of range | H14: =IF(D14=0,0,F14/D14-1) -> -0.536 | I14: Guide £100–£500/m. UFS figure = base + 120 tx/month
A15: Ad hoc / advisory | B15: per hour | C15: 50 | D15: 100 | E15: 200 | F15: ='Rate Card'!$B$45 -> 90 | G15: =IF(F15<C15,"Below market",IF(F15>E15,"Above market",IF(F15<D15,"Low end of range","High end of range"))) -> Low end of range | H15: =IF(D15=0,0,F15/D15-1) -> -0.1 | I15: Watford £50–£200/hr
A16: Alphabet share restructure | B16: one-off | C16: 350 | D16: 450 | E16: 630 | F16: ='Rate Card'!$B$41 -> 450 | G16: =IF(F16<C16,"Below market",IF(F16>E16,"Above market",IF(F16<D16,"Low end of range","High end of range"))) -> High end of range | H16: =IF(D16=0,0,F16/D16-1) -> 0 | I16: Facebook group: £350–£450 accountants; £630 solicitor

Sheet Same Client Test
A1: Same client, priced under each competitor's model
A2: Client: Ltd company, £90k–£250k turnover, VAT registered, 3 staff on monthly payroll, 2 director SA returns, 120 transactions/month. Where a firm doesn't publish a fee, the market typical from Market Comparison is used (marked 'assumed').
A4: Firm / model | B4: Monthly package | C4: Bookkeeping /yr | D4: VAT /yr | E4: Payroll /yr | F4: SA x2 /yr | G4: Annual total (ex VAT) | H4: Notes
A5: UFS (your Quote Calculator) | G5: ='Quote Calculator'!C52 -> 5313.3 | H5: Your full recurring quote for the example client
A6: RSBC-style low-cost package | B6: 480 | C6: ='Market Comparison'!D13*12 -> 948 | D6: =4*'Market Comparison'!D9 -> 400 | E6: ='Market Comparison'!D11*12 -> 600 | F6: =2*'Market Comparison'!D5 -> 398 | G6: =SUM(B6:F6) -> 2826 | H6: Package £40/m; add-ons assumed at market typical
A7: A-Wise headline (discounted) | B7: 240 | C7: ='Market Comparison'!D13*12 -> 948 | D7: =4*'Market Comparison'!D9 -> 400 | E7: ='Market Comparison'!D11*12 -> 600 | F7: =2*'Market Comparison'!D5 -> 398 | G7: =SUM(B7:F7) -> 2586 | H7: £20/m headline; add-ons assumed
A8: Itemised menu (Herts listing) | B8: 0 | C8: ='Market Comparison'!D13*12 -> 948 | D8: =4*89 -> 356 | E8: =12*29 -> 348 | F8: =2*'Market Comparison'!D5 -> 398 | G8: =SUM(B8:F8)+'Market Comparison'!D7 -> 3150 | H8: £89 VAT and £29 payroll from listing; bookkeeping, SA and accounts+CT (£1,100) at market typical
A9: Traditional Herts firm (guide typical) | B9: 0 | C9: ='Market Comparison'!D13*12 -> 948 | D9: =4*'Market Comparison'!D9 -> 400 | E9: =MAX('Market Comparison'!D11,3*'Market Comparison'!D10)*12 -> 600 | F9: =2*'Market Comparison'!D5 -> 398 | G9: =SUM(B9:F9)+'Market Comparison'!D7 -> 3446 | H9: All at guide typical, incl. accounts+CT £1,100
A11: UFS vs cheapest competitor model | G11: =G5-MIN(G6:G9) -> 2727.3
A12: Note: UFS total includes management accounts, dividend paperwork, registered office and the records multiplier, which the others exclude. Compare like for like by switching those off in the Quote Calculator.
